Workbook

Sheet How to Use
A1: Document 26 — Validation Timing Checklist
A2: How to use this workbook. It is the tick-list for document 25, the Validation Timing Guide: one row for every check at every gate, in build order, and a log for re-validation after the build. Document 25 says why and how; this workbook is where you mark it done.
A4: THE TABS
B6: Gate Summary | C6: One line per gate: how many checks, how many passed, failed or still to go, and the gate’s status. All formulas. Click a gate code to jump to it.
B7: Build Checklist | C7: Ten gates, G0 to G9, and 76 checks in build order. This is the tab you fill in.
B8: Re-validation Log | C8: One row per event after the build — a reload, a measure edit, a changed visual. Pick the Event and the tab tells you what to re-run.
B9: Triggers | C9: The eleven events from document 25 Table 4.1, with what each requires. Reference only; the Re-validation Log reads from it.
A10: RECORDING THE INITIAL BUILD
A12: 1 | B12: Work on the Build Checklist from the top. Do not start a gate’s work until the gate before it reads PASSED on the Gate Summary tab.
A13: 2 | B13: For each row, set Result (Pass, Fail, N/A or Not run), the Date, and Checked by. Put the number you saw in Observed value — “330,080 staged / 330,080 loaded”, not “ok”.
A14: 3 | B14: When a row carries a Suite number, the column beside it says “Yes — check n”. Record that result in document 22 as well, on the Check Results tab, against the same check. Doc 22 is the formal record of the seventeen; this workbook is the working tick-list. The Procedure column on the same row names the step-by-step document for that check in docs/validation/ — open it if you have not run the check before.
A15: 4 | B15: G5 and G8 are the two passes. G5 ends with doc 22 Run 1 reading INCOMPLETE — 5 not recorded; G8 ends with it reading PASS. Both are rows here, so the checklist cannot be completed while doc 22 disagrees.
A16: 5 | B16: A Fail stops the gate. The Gate Summary reads BLOCKED until the row is fixed and re-recorded as Pass. Log the failure on the doc 22 Failure Log as well.
A17: WHAT THE GATE STATUS MEANS
B19: PASSED | C19: Every row in the gate is Pass or N/A. Start the next gate.
B20: OPEN — n to go | C20: Rows still at Not run or blank. The number is how many.
B21: BLOCKED | C21: At least one row is Fail. Nothing downstream of this gate should be built on it.
B22: All: COMPLETE | C22: The bottom summary line: every row in every gate is Pass or N/A. The initial build is validated.
A23: AFTER THE BUILD
A25: 1 | B25: When one of the Triggers happens, add a row to the Re-validation Log with the date and the Event.
A26: 2 | B26: What to re-run and the Doc 22 Trigger fill themselves in. Run those checks, then record the Result — and the Run ID if you started a new run in document 22.
A27: 3 | B27: Something not on the list? Type it in Event anyway; What to re-run reads “not a listed event”. Add it to the Triggers tab if it will happen again.
A28: RULES
A30: • | B30: N/A needs a reason in Observed value / notes. Skipped is not N/A — leave it as Not run.
A31: • | B31: To add a check, insert a row inside the gate on the Build Checklist and set its Gate code in column A. The Gate Summary counts it automatically — rows up to 600 are covered.
A32: • | B32: Do not type on the Gate Summary tab, or over the formula columns: Also record in doc 22 on the Build Checklist, and What to re-run and Doc 22 Trigger on the Re-validation Log.
A33: WHERE THIS COMES FROM
B35: Document 25 | C35: Validation Timing Guide — every gate, check and trigger on these tabs is taken from it.
B36: Document 22 | C36: Validation and QA Results — the formal record of the seventeen suite checks.
B37: Document 21 | C37: Development Checklist — the build tasks. Its phases map to the gates: G0 = Phases 0–1, G1 = 2, G2 = 3, G3 = 4, G4 = 5, G5 = 6, G6 = 7, G7 and G8 = 8, G9 = 9.
B38: docs/validation/ | C38: One step-by-step procedure per suite check, V01 to V17, in .docx and .xlsx. The Procedure column on the Build Checklist names the one that covers each row.

Sheet Gate Summary
A1: Gate Summary — the initial build, gate by gate
A2: Every figure here is a formula counting the Result column on the Build Checklist tab. Do not type on this tab. A gate is PASSED when all its rows are Pass or N/A; start the next gate only then.
A4: Gate | B4: Name | C4: Run it | D4: Checks | E4: Pass | F4: Fail | G4: N/A | H4: Not yet | I4: Gate status | J4: Doc 25
A5: G0 | B5: Repository and environment | C5: Before any build step | D5: =COUNTIF('Build Checklist'!$A$5:$A$600,$A5) | E5: =COUNTIFS('Build Checklist'!$A$5:$A$600,$A5,'Build Checklist'!$H$5:$H$600,"Pass") | F5: =COUNTIFS('Build Checklist'!$A$5:$A$600,$A5,'Build Checklist'!$H$5:$H$600,"Fail") | G5: =COUNTIFS('Build Checklist'!$A$5:$A$600,$A5,'Build Checklist'!$H$5:$H$600,"N/A") | H5: =$D5-$E5-$F5-$G5 | I5: =IF($D5=0,"",IF($F5>0,"BLOCKED",IF($H5=0,"PASSED","OPEN — "&$H5&" to go"))) | J5: §3.1
A6: G1 | B6: Warehouse | C6: After each SQL script, before the next | D6: =COUNTIF('Build Checklist'!$A$5:$A$600,$A6) | E6: =COUNTIFS('Build Checklist'!$A$5:$A$600,$A6,'Build Checklist'!$H$5:$H$600,"Pass") | F6: =COUNTIFS('Build Checklist'!$A$5:$A$600,$A6,'Build Checklist'!$H$5:$H$600,"Fail") | G6: =COUNTIFS('Build Checklist'!$A$5:$A$600,$A6,'Build Checklist'!$H$5:$H$600,"N/A") | H6: =$D6-$E6-$F6-$G6 | I6: =IF($D6=0,"",IF($F6>0,"BLOCKED",IF($H6=0,"PASSED","OPEN — "&$H6&" to go"))) | J6: §3.2
A7: G2 | B7: Power Query sources | C7: After each source query | D7: =COUNTIF('Build Checklist'!$A$5:$A$600,$A7) | E7: =COUNTIFS('Build Checklist'!$A$5:$A$600,$A7,'Build Checklist'!$H$5:$H$600,"Pass") | F7: =COUNTIFS('Build Checklist'!$A$5:$A$600,$A7,'Build Checklist'!$H$5:$H$600,"Fail") | G7: =COUNTIFS('Build Checklist'!$A$5:$A$600,$A7,'Build Checklist'!$H$5:$H$600,"N/A") | H7: =$D7-$E7-$F7-$G7 | I7: =IF($D7=0,"",IF($F7>0,"BLOCKED",IF($H7=0,"PASSED","OPEN — "&$H7&" to go"))) | J7: §3.3
A8: G3 | B8: Model structure | C8: After relationships and configuration, before any measure | D8: =COUNTIF('Build Checklist'!$A$5:$A$600,$A8) | E8: =COUNTIFS('Build Checklist'!$A$5:$A$600,$A8,'Build Checklist'!$H$5:$H$600,"Pass") | F8: =COUNTIFS('Build Checklist'!$A$5:$A$600,$A8,'Build Checklist'!$H$5:$H$600,"Fail") | G8: =COUNTIFS('Build Checklist'!$A$5:$A$600,$A8,'Build Checklist'!$H$5:$H$600,"N/A") | H8: =$D8-$E8-$F8-$G8 | I8: =IF($D8=0,"",IF($F8>0,"BLOCKED",IF($H8=0,"PASSED","OPEN — "&$H8&" to go"))) | J8: §3.4
A9: G4 | B9: Measures | C9: As each measure folder closes | D9: =COUNTIF('Build Checklist'!$A$5:$A$600,$A9) | E9: =COUNTIFS('Build Checklist'!$A$5:$A$600,$A9,'Build Checklist'!$H$5:$H$600,"Pass") | F9: =COUNTIFS('Build Checklist'!$A$5:$A$600,$A9,'Build Checklist'!$H$5:$H$600,"Fail") | G9: =COUNTIFS('Build Checklist'!$A$5:$A$600,$A9,'Build Checklist'!$H$5:$H$600,"N/A") | H9: =$D9-$E9-$F9-$G9 | I9: =IF($D9=0,"",IF($F9>0,"BLOCKED",IF($H9=0,"PASSED","OPEN — "&$H9&" to go"))) | J9: §3.5
A10: G5 | B10: MODEL PASS | C10: Before publishing the model | D10: =COUNTIF('Build Checklist'!$A$5:$A$600,$A10) | E10: =COUNTIFS('Build Checklist'!$A$5:$A$600,$A10,'Build Checklist'!$H$5:$H$600,"Pass") | F10: =COUNTIFS('Build Checklist'!$A$5:$A$600,$A10,'Build Checklist'!$H$5:$H$600,"Fail") | G10: =COUNTIFS('Build Checklist'!$A$5:$A$600,$A10,'Build Checklist'!$H$5:$H$600,"N/A") | H10: =$D10-$E10-$F10-$G10 | I10: =IF($D10=0,"",IF($F10>0,"BLOCKED",IF($H10=0,"PASSED","OPEN — "&$H10&" to go"))) | J10: §3.6
A11: G6 | B11: Publish and bind | C11: After publishing the model | D11: =COUNTIF('Build Checklist'!$A$5:$A$600,$A11) | E11: =COUNTIFS('Build Checklist'!$A$5:$A$600,$A11,'Build Checklist'!$H$5:$H$600,"Pass") | F11: =COUNTIFS('Build Checklist'!$A$5:$A$600,$A11,'Build Checklist'!$H$5:$H$600,"Fail") | G11: =COUNTIFS('Build Checklist'!$A$5:$A$600,$A11,'Build Checklist'!$H$5:$H$600,"N/A") | H11: =$D11-$E11-$F11-$G11 | I11: =IF($D11=0,"",IF($F11>0,"BLOCKED",IF($H11=0,"PASSED","OPEN — "&$H11&" to go"))) | J11: §3.7
A12: G7 | B12: Report build | C12: As each report page is finished | D12: =COUNTIF('Build Checklist'!$A$5:$A$600,$A12) | E12: =COUNTIFS('Build Checklist'!$A$5:$A$600,$A12,'Build Checklist'!$H$5:$H$600,"Pass") | F12: =COUNTIFS('Build Checklist'!$A$5:$A$600,$A12,'Build Checklist'!$H$5:$H$600,"Fail") | G12: =COUNTIFS('Build Checklist'!$A$5:$A$600,$A12,'Build Checklist'!$H$5:$H$600,"N/A") | H12: =$D12-$E12-$F12-$G12 | I12: =IF($D12=0,"",IF($F12>0,"BLOCKED",IF($H12=0,"PASSED","OPEN — "&$H12&" to go"))) | J12: §3.8
A13: G8 | B13: REPORT PASS | C13: Before publishing each report | D13: =COUNTIF('Build Checklist'!$A$5:$A$600,$A13) | E13: =COUNTIFS('Build Checklist'!$A$5:$A$600,$A13,'Build Checklist'!$H$5:$H$600,"Pass") | F13: =COUNTIFS('Build Checklist'!$A$5:$A$600,$A13,'Build Checklist'!$H$5:$H$600,"Fail") | G13: =COUNTIFS('Build Checklist'!$A$5:$A$600,$A13,'Build Checklist'!$H$5:$H$600,"N/A") | H13: =$D13-$E13-$F13-$G13 | I13: =IF($D13=0,"",IF($F13>0,"BLOCKED",IF($H13=0,"PASSED","OPEN — "&$H13&" to go"))) | J13: §3.9
A14: G9 | B14: Packaging | C14: Before the final push | D14: =COUNTIF('Build Checklist'!$A$5:$A$600,$A14) | E14: =COUNTIFS('Build Checklist'!$A$5:$A$600,$A14,'Build Checklist'!$H$5:$H$600,"Pass") | F14: =COUNTIFS('Build Checklist'!$A$5:$A$600,$A14,'Build Checklist'!$H$5:$H$600,"Fail") | G14: =COUNTIFS('Build Checklist'!$A$5:$A$600,$A14,'Build Checklist'!$H$5:$H$600,"N/A") | H14: =$D14-$E14-$F14-$G14 | I14: =IF($D14=0,"",IF($F14>0,"BLOCKED",IF($H14=0,"PASSED","OPEN — "&$H14&" to go"))) | J14: §3.10
A15: All | B15: Initial build | D15: =SUM(D5:D14) | E15: =SUM(E5:E14) | F15: =SUM(F5:F14) | G15: =SUM(G5:G14) | H15: =SUM(H5:H14) | I15: =IF($F15>0,"BLOCKED — "&$F15&" failing",IF($H15=0,"COMPLETE",TEXT(($E15+$G15)/$D15,"0%")&" done"))

Sheet Build Checklist
A1: Build Checklist — every check at every gate, in build order
A2: The recording companion to document 25. Work down the gates in order and set Result on every row; the Gate Summary tab counts itself from this column. A row with a Suite number is also recorded in document 22 against the same check. A gate is PASSED when every row is Pass or N/A. The Procedure column names the step-by-step document for that check in docs/validation/ — one file per check, V01 to V17.
A4: Gate | B4: Ref | C4: Check | D4: Pass when | E4: Where | F4: Suite # | G4: Also record in doc 22 | H4: Result | I4: Date | J4: Checked by | K4: Observed value / notes | L4: Procedure
A5: G0 — REPOSITORY AND ENVIRONMENT · Before any build step · doc 25 §3.1
A6: G0 | B6: G0.01 | C6: .gitignore committed before the first file | D6: The first commit already contains .gitignore | E6: Doc 00 §4.3 | G6: =IF($F6="","",IF(ISNUMBER(SEARCH(",",$F6)),"Yes — checks ","Yes — check ")&$F6) | H6: Not run
A7: G0 | B7: G0.02 | C7: Clone in place | D7: git status runs from X:\retail-sector-health with a clean working tree | E7: Doc 00 §5 | G7: =IF($F7="","",IF(ISNUMBER(SEARCH(",",$F7)),"Yes — checks ","Yes — check ")&$F7) | H7: Not run
A8: G0 | B8: G0.03 | C8: Environment matches the verified build | D8: SSMS 22 connects to BRUNO\MSSQLSERVER01; versions match doc 02 Table 2.1 | E8: Doc 02 §2.1 | G8: =IF($F8="","",IF(ISNUMBER(SEARCH(",",$F8)),"Yes — checks ","Yes — check ")&$F8) | H8: Not run
A9: G1 — WAREHOUSE · After each SQL script, before the next · doc 25 §3.2
A10: G1 | B10: G1.01 | C10: sql/01 create database | D10: sys.schemas returns stg and dw | E10: sql/01 header | G10: =IF($F10="","",IF(ISNUMBER(SEARCH(",",$F10)),"Yes — checks ","Yes — check ")&$F10) | H10: Not run
A11: G1 | B11: G1.02 | C11: sql/02 staging table | D11: Final SELECT returns approximately 330,080 rows | E11: sql/02 header | G11: =IF($F11="","",IF(ISNUMBER(SEARCH(",",$F11)),"Yes — checks ","Yes — check ")&$F11) | H11: Not run
A12: G1 | B12: G1.03 | C12: sql/03 profiling queries | D12: Five result sets read and noted in doc 21 | E12: sql/03 header; doc 02 §5.5 | G12: =IF($F12="","",IF(ISNUMBER(SEARCH(",",$F12)),"Yes — checks ","Yes — check ")&$F12) | H12: Not run
A13: G1 | B13: G1.04 | C13: sql/04 dimensions | D13: Each dimension has rows and no duplicate business key | E13: sql/04 header | G13: =IF($F13="","",IF(ISNUMBER(SEARCH(",",$F13)),"Yes — checks ","Yes — check ")&$F13) | H13: Not run
A14: G1 | B14: G1.05 | C14: sql/05 fact and load procedure | D14: Staged-versus-loaded reconciliation shows no unexplained gap | E14: sql/05 header | F14: 1 | G14: =IF($F14="","",IF(ISNUMBER(SEARCH(",",$F14)),"Yes — checks ","Yes — check ")&$F14) | H14: Not run | L14: V01
A15: G1 | B15: G1.06 | C15: sql/06 item lifecycle | D15: No NULL lifecycle column for an item with movement; MAX(LastSeenDateKey) = MAX(DateKey) | E15: sql/06 header; doc 25 §3.2 | F15: 12 | G15: =IF($F15="","",IF(ISNUMBER(SEARCH(",",$F15)),"Yes — checks ","Yes — check ")&$F15) | H15: Not run | L15: V12
A16: G1 | B16: G1.07 | C16: sql/07 indexes | D16: sys.indexes shows the columnstore index on dw.FactItemMovement | E16: sql/07 header | G16: =IF($F16="","",IF(ISNUMBER(SEARCH(",",$F16)),"Yes — checks ","Yes — check ")&$F16) | H16: Not run
A17: G1 | B17: G1.08 | C17: sql/08 presentation views | D17: SELECT TOP 10 * FROM dw.vw_ItemMovement returns resolved attributes | E17: sql/08 header | G17: =IF($F17="","",IF(ISNUMBER(SEARCH(",",$F17)),"Yes — checks ","Yes — check ")&$F17) | H17: Not run
A18: G2 — POWER QUERY SOURCES · After each source query · doc 25 §3.3
A19: G2 | B19: G2.01 | C19: Discovery query, run once | D19: Returned codes reconcile with doc 02 Table 3.1; load then disabled | E19: Doc 02 §3.4 | G19: =IF($F19="","",IF(ISNUMBER(SEARCH(",",$F19)),"Yes — checks ","Yes — check ")&$F19) | H19: Not run
A20: G2 | B20: G2.02 | C20: FactSectorSales | D20: One row per month for 44X72 from pStartPeriod through the latest month Census has published, no gap | E20: Doc 02 §3.5 | F20: 2 | G20: =IF($F20="","",IF(ISNUMBER(SEARCH(",",$F20)),"Yes — checks ","Yes — check ")&$F20) | H20: Not run | L20: V02
A21: G2 | B21: G2.03 | C21: FactMacro | D21: Nine SeriesId values, each with a monthly series | E21: Doc 02 §4.3 | G21: =IF($F21="","",IF(ISNUMBER(SEARCH(",",$F21)),"Yes — checks ","Yes — check ")&$F21) | H21: Not run
A22: G2 | B22: G2.04 | C22: DimCategory | D22: Referential coverage query returns zero rows | E22: Doc 02 §6.5 | F22: 5 | G22: =IF($F22="","",IF(ISNUMBER(SEARCH(",",$F22)),"Yes — checks ","Yes — check ")&$F22) | H22: Not run | L22: V05
A23: G2 | B23: G2.05 | C23: DimItem merge | D23: No blank BeverageClass; unmatched types show as Unmapped | E23: Doc 02 §6.3 | G23: =IF($F23="","",IF(ISNUMBER(SEARCH(",",$F23)),"Yes — checks ","Yes — check ")&$F23) | H23: Not run
A24: G2 | B24: G2.06 | C24: Every query | D24: No key= literal; pCensusKey and pRefMappingsPath used only as parameters | E24: Doc 02 §3.1, §6.1 | G24: =IF($F24="","",IF(ISNUMBER(SEARCH(",",$F24)),"Yes — checks ","Yes — check ")&$F24) | H24: Not run
A25: G3 — MODEL STRUCTURE · After relationships and configuration, before any measure · doc 25 §3.4
A26: G3 | B26: G3.01 | C26: Auto-detected relationships removed | D26: Only the seven relationships of doc 02 §7.2 exist | E26: Doc 02 §7 | G26: =IF($F26="","",IF(ISNUMBER(SEARCH(",",$F26)),"Yes — checks ","Yes — check ")&$F26) | H26: Not run
A27: G3 | B27: G3.02 | C27: Model view against Figure 7.1 | D27: Seven lines, all one-to-many, single-direction, on the right columns | E27: Doc 02 Figure 7.1 | G27: =IF($F27="","",IF(ISNUMBER(SEARCH(",",$F27)),"Yes — checks ","Yes — check ")&$F27) | H27: Not run
A28: G3 | B28: G3.03 | C28: Date relationship integrity | D28: No blank DimDate row — DAX query returns 0 | E28: Doc 25 §3.4 | F28: 6 | G28: =IF($F28="","",IF(ISNUMBER(SEARCH(",",$F28)),"Yes — checks ","Yes — check ")&$F28) | H28: Not run | L28: V06
A29: G3 | B29: G3.04 | C29: Model configuration | D29: Date table marked; sort-by columns set; keys hidden; Do Not Summarize | E29: Doc 02 §7.3 | G29: =IF($F29="","",IF(ISNUMBER(SEARCH(",",$F29)),"Yes — checks ","Yes — check ")&$F29) | H29: Not run
A30: G4 — MEASURES · As each measure folder closes · doc 25 §3.5
A31: G4 | B31: G4.01 | C31: Folder 01 Macro closes | D31: CPI Index for a known month matches FRED CPIAUCSL | E31: Doc 02 Table 8.2; doc 25 §3.5 | G31: =IF($F31="","",IF(ISNUMBER(SEARCH(",",$F31)),"Yes — checks ","Yes — check ")&$F31) | H31: Not run
A32: G4 | B32: G4.02 | C32: Folder 02 Sector closes | D32: Census 452 matches FRED MRTSSM452USS within rounding; category gaps recorded | E32: Doc 02 Table 8.2; doc 25 §3.5 | F32: 3, 4 | G32: =IF($F32="","",IF(ISNUMBER(SEARCH(",",$F32)),"Yes — checks ","Yes — check ")&$F32) | H32: Not run | L32: V03, V04
A33: G4 | B33: G4.03 | C33: Folder 03 Micro closes | D33: Total Cases equals SUM(TotalMovement) in SQL; Return Rows non-zero | E33: Doc 02 Table 8.2; doc 25 §3.5 | F33: 11 | G33: =IF($F33="","",IF(ISNUMBER(SEARCH(",",$F33)),"Yes — checks ","Yes — check ")&$F33) | H33: Not run | L33: V11
A34: G4 | B34: G4.04 | C34: Folder 04 Cross-Tier closes | D34: National Liquor Stores Real Sales moves with RRSFS | E34: Doc 02 Table 8.2 | G34: =IF($F34="","",IF(ISNUMBER(SEARCH(",",$F34)),"Yes — checks ","Yes — check ")&$F34) | H34: Not run
A35: G4 | B35: G4.05 | C35: Folder 05 Channel closes | D35: 2019 baseline query returns no rows for any class, type and year; national series direction recorded | E35: Doc 02 Table 8.2; doc 25 §3.5 | F35: 9, 10 | G35: =IF($F35="","",IF(ISNUMBER(SEARCH(",",$F35)),"Yes — checks ","Yes — check ")&$F35) | H35: Not run | L35: V09, V10
A36: G4 | B36: G4.06 | C36: Folder 06 Elasticity closes | D36: Observation Count non-zero and plausible | E36: Doc 02 Table 8.2; doc 25 §3.5 | G36: =IF($F36="","",IF(ISNUMBER(SEARCH(",",$F36)),"Yes — checks ","Yes — check ")&$F36) | H36: Not run
A37: G4 | B37: G4.07 | C37: Folder 07 Rotation closes | D37: Rate Sensitivity Beta negative for 441, 442 and 444 | E37: Doc 02 Table 8.2; doc 25 §3.5 | G37: =IF($F37="","",IF(ISNUMBER(SEARCH(",",$F37)),"Yes — checks ","Yes — check ")&$F37) | H37: Not run
A38: G4 | B38: G4.08 | C38: Folder 08 Assortment closes | D38: Cohort Size by year sums to the DimItem row count; Cumulative Cases % is exactly 1 at the lowest rank | E38: Doc 02 Table 8.2; doc 25 §3.5 | F38: 13, 14 | G38: =IF($F38="","",IF(ISNUMBER(SEARCH(",",$F38)),"Yes — checks ","Yes — check ")&$F38) | H38: Not run | L38: V13, V14
A39: G4 | B39: G4.09 | C39: Folder 09 Supplier closes | D39: Supplier HHI between 0 and 10,000 | E39: Doc 02 Table 8.2; doc 25 §3.5 | G39: =IF($F39="","",IF(ISNUMBER(SEARCH(",",$F39)),"Yes — checks ","Yes — check ")&$F39) | H39: Not run
A40: G4 | B40: G4.10 | C40: Folder 10 Seasonality closes | D40: The twelve seasonal factors average approximately 1.00 | E40: Doc 02 Table 8.2; doc 25 §3.5 | G40: =IF($F40="","",IF(ISNUMBER(SEARCH(",",$F40)),"Yes — checks ","Yes — check ")&$F40) | H40: Not run
A41: G5 — MODEL PASS · Before publishing the model · doc 25 §3.6
...

Sheet Re-validation Log
A1: Re-validation Log — after the build
A2: One row per event. Choose the Event; What to re-run and the doc 22 Trigger fill in from the Triggers tab. Record the result, and the doc 22 Run ID if the event started a run there.
A4: Date | B4: Event | C4: What changed | D4: What to re-run | E4: Doc 22 Trigger | F4: Result | G4: Doc 22 Run ID | H4: Checked by | I4: Notes
D5: =IF($B5="","",IFERROR(VLOOKUP($B5,Triggers!$A$5:$C$40,2,FALSE),"— not a listed event")) | E5: =IF($B5="","",IFERROR(VLOOKUP($B5,Triggers!$A$5:$C$40,3,FALSE),""))
D6: =IF($B6="","",IFERROR(VLOOKUP($B6,Triggers!$A$5:$C$40,2,FALSE),"— not a listed event")) | E6: =IF($B6="","",IFERROR(VLOOKUP($B6,Triggers!$A$5:$C$40,3,FALSE),""))
D7: =IF($B7="","",IFERROR(VLOOKUP($B7,Triggers!$A$5:$C$40,2,FALSE),"— not a listed event")) | E7: =IF($B7="","",IFERROR(VLOOKUP($B7,Triggers!$A$5:$C$40,3,FALSE),""))
D8: =IF($B8="","",IFERROR(VLOOKUP($B8,Triggers!$A$5:$C$40,2,FALSE),"— not a listed event")) | E8: =IF($B8="","",IFERROR(VLOOKUP($B8,Triggers!$A$5:$C$40,3,FALSE),""))
D9: =IF($B9="","",IFERROR(VLOOKUP($B9,Triggers!$A$5:$C$40,2,FALSE),"— not a listed event")) | E9: =IF($B9="","",IFERROR(VLOOKUP($B9,Triggers!$A$5:$C$40,3,FALSE),""))
D10: =IF($B10="","",IFERROR(VLOOKUP($B10,Triggers!$A$5:$C$40,2,FALSE),"— not a listed event")) | E10: =IF($B10="","",IFERROR(VLOOKUP($B10,Triggers!$A$5:$C$40,3,FALSE),""))
D11: =IF($B11="","",IFERROR(VLOOKUP($B11,Triggers!$A$5:$C$40,2,FALSE),"— not a listed event")) | E11: =IF($B11="","",IFERROR(VLOOKUP($B11,Triggers!$A$5:$C$40,3,FALSE),""))
D12: =IF($B12="","",IFERROR(VLOOKUP($B12,Triggers!$A$5:$C$40,2,FALSE),"— not a listed event")) | E12: =IF($B12="","",IFERROR(VLOOKUP($B12,Triggers!$A$5:$C$40,3,FALSE),""))
D13: =IF($B13="","",IFERROR(VLOOKUP($B13,Triggers!$A$5:$C$40,2,FALSE),"— not a listed event")) | E13: =IF($B13="","",IFERROR(VLOOKUP($B13,Triggers!$A$5:$C$40,3,FALSE),""))
D14: =IF($B14="","",IFERROR(VLOOKUP($B14,Triggers!$A$5:$C$40,2,FALSE),"— not a listed event")) | E14: =IF($B14="","",IFERROR(VLOOKUP($B14,Triggers!$A$5:$C$40,3,FALSE),""))
D15: =IF($B15="","",IFERROR(VLOOKUP($B15,Triggers!$A$5:$C$40,2,FALSE),"— not a listed event")) | E15: =IF($B15="","",IFERROR(VLOOKUP($B15,Triggers!$A$5:$C$40,3,FALSE),""))
D16: =IF($B16="","",IFERROR(VLOOKUP($B16,Triggers!$A$5:$C$40,2,FALSE),"— not a listed event")) | E16: =IF($B16="","",IFERROR(VLOOKUP($B16,Triggers!$A$5:$C$40,3,FALSE),""))
... D300: =IF($B300="","",IFERROR(VLOOKUP($B300,Triggers!$A$5:$C$40,2,FALSE),"— not a listed event")) | E300: =IF($B300="","",IFERROR(VLOOKUP($B300,Triggers!$A$5:$C$40,3,FALSE),""))

Sheet Triggers
A1: Triggers — the events that call for re-validation
A2: Document 25 Table 4.1. The Event list on the Re-validation Log reads from this tab; add a row here to make a new event selectable.
A4: Event | B4: What to re-run | C4: Doc 22 Trigger
A5: A fact table reloads with new data | B5: sql/06 first if the county data moved; then the twelve data checks 1–6, 9–14 | C5: Post fact-table reload
A6: A measure is edited | B6: That folder's closing check; every folder whose Depends on names it; any suite check naming it; then republish | C6: Post measure change
A7: A relationship or model setting changes | B7: Figure 7.1 comparison; check 6; all ten folder closing checks; then the model pass | C7: Ad hoc
A8: RefMappings.xlsx is edited | B8: Check 5; look for Unmapped in slicers; check 3 if IsAggregate changed | C8: Ad hoc
A9: Census changes its category set | B9: Doc 02 §3.4 discovery; update Table 3.1 and RefMappings.xlsx; checks 5 and 3 | C9: Ad hoc
A10: A report visual is added or changed | B10: Checks 7 and 8 on that page; any of 9, 11, 14, 15, 16 it carries; 17 | C10: Post report change
A11: A theme .json is edited | B11: Re-apply the theme; the three theme checks in doc 15 §3.3 | C11: Not recorded in doc 22
A12: The model is republished | B12: First refresh succeeds; check 17 on each report | C12: Pre-publication
A13: Before any push to GitHub | B13: Search for key= and .csv | C13: Not recorded in doc 22
A14: A sql/04, 05 or 06 script is edited | B14: sql/04 to 06 in order; checks 1, 12 and 13; then the rest of the twelve data checks | C14: Ad hoc
A15: A Power Query source query or parameter is edited | B15: Checks 2, 4 and 6; then 3 and 5 | C15: Ad hoc
